<?xml version="1.0"?>
<robot name="smart_wheelchair">

  <!-- Base Link -->
  <link name="base_link">
    <visual>
      <geometry><box size="0.6 0.4 0.2"/></geometry>
      <material name="blue"><color rgba="0 0 1 1"/></material>
    </visual>
    <collision>
      <geometry><box size="0.6 0.4 0.2"/></geometry>
    </collision>
    <inertial>
      <mass value="10.0"/>
      <inertia ixx="0.166" ixy="0.0" ixz="0.0" iyy="0.333" iyz="0.0" izz="0.466"/>
    </inertial>
  </link>

  <!-- Left Wheel -->
  <link name="left_wheel">
    <visual>
      <geometry><cylinder length="0.05" radius="0.1"/></geometry>
      <material name="black"><color rgba="0 0 0 1"/></material>
    </visual>
    <collision>
      <origin rpy="0 0 0" xyz="0 0 0"/>
      <geometry><cylinder length="0.05" radius="0.1"/></geometry>
    </collision>
    <inertial>
      <mass value="1.0"/>
      <inertia ixx="0.0027" ixy="0" ixz="0" iyy="0.0027" iyz="0" izz="0.005"/>
    </inertial>
  </link>
  
  <joint name="left_wheel_joint" type="continuous">
    <parent link="base_link"/>
    <child link="left_wheel"/>
    <origin xyz="0 0.22 -0.05" rpy="-1.5708 0 0"/>
    <axis xyz="0 0 1"/>
  </joint>

  <!-- Right Wheel -->
  <link name="right_wheel">
    <visual>
      <geometry><cylinder length="0.05" radius="0.1"/></geometry>
      <material name="black"><color rgba="0 0 0 1"/></material>
    </visual>
    <collision>
      <origin rpy="0 0 0" xyz="0 0 0"/>
      <geometry><cylinder length="0.05" radius="0.1"/></geometry>
    </collision>
    <inertial>
      <mass value="1.0"/>
      <inertia ixx="0.0027" ixy="0" ixz="0" iyy="0.0027" iyz="0" izz="0.005"/>
    </inertial>
  </link>

  <joint name="right_wheel_joint" type="continuous">
    <parent link="base_link"/>
    <child link="right_wheel"/>
    <origin xyz="0 -0.22 -0.05" rpy="-1.5708 0 0"/>
    <axis xyz="0 0 1"/>
  </joint>

  <!-- Lidar -->
  <link name="lidar_link">
    <visual>
      <geometry><cylinder length="0.05" radius="0.05"/></geometry>
      <material name="red"><color rgba="1 0 0 1"/></material>
    </visual>
    <collision>
      <geometry><cylinder length="0.05" radius="0.05"/></geometry>
    </collision>
    <inertial>
      <mass value="0.1"/>
      <inertia ixx="0.0001" ixy="0" ixz="0" iyy="0.0001" iyz="0" izz="0.0001"/>
    </inertial>
  </link>

  <joint name="lidar_joint" type="fixed">
    <parent link="base_link"/>
    <child link="lidar_link"/>
    <origin xyz="0.2 0 0.125" rpy="0 0 0"/>
  </joint>

  <!-- Camera -->
  <link name="camera_link">
    <visual>
      <geometry><box size="0.02 0.1 0.02"/></geometry>
      <material name="green"><color rgba="0 1 0 1"/></material>
    </visual>
    <collision>
      <geometry><box size="0.02 0.1 0.02"/></geometry>
    </collision>
    <inertial>
      <mass value="0.05"/>
      <inertia ixx="0.00001" ixy="0" ixz="0" iyy="0.00001" iyz="0" izz="0.00001"/>
    </inertial>
  </link>

  <joint name="camera_joint" type="fixed">
    <parent link="base_link"/>
    <child link="camera_link"/>
    <origin xyz="0.3 0 0.05" rpy="0 0 0"/>
  </joint>

  <!-- Gazebo Material Colors -->
  <gazebo reference="base_link">
    <material>Gazebo/Blue</material>
  </gazebo>
  <gazebo reference="left_wheel">
    <material>Gazebo/Black</material>
  </gazebo>
  <gazebo reference="right_wheel">
    <material>Gazebo/Black</material>
  </gazebo>
  <gazebo reference="lidar_link">
    <material>Gazebo/Red</material>
  </gazebo>
  <gazebo reference="camera_link">
    <material>Gazebo/Green</material>
  </gazebo>
  <gazebo reference="front_caster">
    <material>Gazebo/Grey</material>
    <mu1 value="0.001"/>
    <mu2 value="0.001"/>
  </gazebo>
  <gazebo reference="rear_caster">
    <material>Gazebo/Grey</material>
    <mu1 value="0.001"/>
    <mu2 value="0.001"/>
  </gazebo>

  <!-- Front Caster Wheel -->
  <link name="front_caster">
    <visual>
      <geometry><sphere radius="0.05"/></geometry>
      <material name="grey"><color rgba="0.5 0.5 0.5 1"/></material>
    </visual>
    <collision>
      <geometry><sphere radius="0.05"/></geometry>
    </collision>
    <inertial>
      <mass value="0.1"/>
      <inertia ixx="0.0001" ixy="0" ixz="0" iyy="0.0001" iyz="0" izz="0.0001"/>
    </inertial>
  </link>
  <joint name="front_caster_joint" type="fixed">
    <parent link="base_link"/>
    <child link="front_caster"/>
    <origin xyz="0.25 0 -0.1" rpy="0 0 0"/>
  </joint>

  <!-- Rear Caster Wheel -->
  <link name="rear_caster">
    <visual>
      <geometry><sphere radius="0.05"/></geometry>
      <material name="grey"><color rgba="0.5 0.5 0.5 1"/></material>
    </visual>
    <collision>
      <geometry><sphere radius="0.05"/></geometry>
    </collision>
    <inertial>
      <mass value="0.1"/>
      <inertia ixx="0.0001" ixy="0" ixz="0" iyy="0.0001" iyz="0" izz="0.0001"/>
    </inertial>
  </link>
  <joint name="rear_caster_joint" type="fixed">
    <parent link="base_link"/>
    <child link="rear_caster"/>
    <origin xyz="-0.25 0 -0.1" rpy="0 0 0"/>
  </joint>

  <!-- Differential Drive Plugin -->
  <gazebo>
    <plugin name='diff_drive' filename='libgazebo_ros_diff_drive.so'>
      <update_rate>30</update_rate>
      <!-- wheels -->
      <left_joint>left_wheel_joint</left_joint>
      <right_joint>right_wheel_joint</right_joint>
      <!-- kinematics -->
      <wheel_separation>0.44</wheel_separation>
      <wheel_diameter>0.2</wheel_diameter>
      <!-- limits -->
      <max_wheel_torque>20</max_wheel_torque>
      <max_wheel_acceleration>1.0</max_wheel_acceleration>
      <!-- output -->
      <publish_odom>true</publish_odom>
      <publish_odom_tf>true</publish_odom_tf>
      <publish_wheel_tf>true</publish_wheel_tf>
      <odometry_frame>odom</odometry_frame>
      <robot_base_frame>base_link</robot_base_frame>
    </plugin>
  </gazebo>

  <!-- Lidar Plugin -->
  <gazebo reference="lidar_link">
    <sensor name="lidar" type="ray">
      <always_on>true</always_on>
      <visualize>true</visualize>
      <update_rate>5</update_rate>
      <ray>
        <scan>
          <horizontal>
            <samples>360</samples>
            <resolution>1.000000</resolution>
            <min_angle>0.000000</min_angle>
            <max_angle>6.280000</max_angle>
          </horizontal>
        </scan>
        <range>
          <min>0.120000</min>
          <max>3.5</max>
          <resolution>0.015000</resolution>
        </range>
        <noise>
          <type>gaussian</type>
          <mean>0.0</mean>
          <stddev>0.01</stddev>
        </noise>
      </ray>
      <plugin name="scan" filename="libgazebo_ros_ray_sensor.so">
        <ros>
          <remapping>~/out:=scan</remapping>
        </ros>
        <output_type>sensor_msgs/LaserScan</output_type>
        <frame_name>lidar_link</frame_name>
      </plugin>
    </sensor>
  </gazebo>

</robot>
